<?xml version="1.0"?>
<robot name="six_dof_arm">

  <!-- Materiali -->
  <material name="gray"><color rgba="0.6 0.6 0.6 1"/></material>
  <material name="blue"><color rgba="0.2 0.3 0.8 1"/></material>

  <!-- BASE -->
  <link name="base_link">
    <visual>
      <origin xyz="0 0 0.05" rpy="0 0 0"/>
      <geometry><box size="0.30 0.30 0.10"/></geometry>
      <material name="gray"/>
    </visual>
    <collision>
      <origin xyz="0 0 0.05" rpy="0 0 0"/>
      <geometry><box size="0.30 0.30 0.10"/></geometry>
    </collision>
  </link>

  <link name="link1">
    <visual>
      <origin xyz="0 0 0.05" rpy="0 0 0"/>
      <geometry><cylinder radius="0.04" length="0.10"/></geometry>
      <material name="blue"/>
    </visual>
    <collision>
      <origin xyz="0 0 0.05" rpy="0 0 0"/>
      <geometry><cylinder radius="0.04" length="0.10"/></geometry>
    </collision>
    <inertial>
      <mass value="1.0"/>
      <inertia ixx="0.005" iyy="0.005" izz="0.005" ixy="0" ixz="0" iyz="0"/>
    </inertial>
  </link>

  <!-- J1: spalla PAN (asse Z) -->
  <joint name="joint1" type="revolute">
    <parent link="base_link"/>
    <child link="link1"/>
    <origin xyz="0 0 0.10" rpy="0 0 0"/>
    <axis xyz="0 0 1"/>
    <limit lower="-3.1416" upper="3.1416" effort="100" velocity="2.0"/>
  </joint>

  <!-- J2: spalla LIFT (asse Y) -->
  <joint name="joint2" type="revolute">
    <parent link="link1"/>
    <child link="link2"/>
    <origin xyz="0 0 0.10" rpy="0 0 0"/>
    <axis xyz="0 1 0"/>
    <limit lower="-2.3562" upper="2.3562" effort="80" velocity="2.0"/>
  </joint>

  <link name="link2">
    <visual>
      <!-- cilindro lungo X -->
      <origin xyz="0.15 0 0" rpy="0 1.5708 0"/>
      <geometry><cylinder radius="0.03" length="0.30"/></geometry>
      <material name="gray"/>
    </visual>
    <collision>
      <origin xyz="0.15 0 0" rpy="0 1.5708 0"/>
      <geometry><cylinder radius="0.03" length="0.30"/></geometry>
    </collision>
    <inertial>
      <mass value="2.0"/>
      <inertia ixx="0.01" iyy="0.01" izz="0.01" ixy="0" ixz="0" iyz="0"/>
    </inertial>
  </link>

  <!-- J3: gomito (asse Y) -->
  <joint name="joint3" type="revolute">
    <parent link="link2"/>
    <child link="link3"/>
    <origin xyz="0.30 0 0" rpy="0 0 0"/>
    <axis xyz="0 1 0"/>
    <limit lower="-2.3562" upper="2.3562" effort="80" velocity="2.0"/>
  </joint>

  <link name="link3">
    <visual>
      <origin xyz="0.15 0 0" rpy="0 1.5708 0"/>
      <geometry><cylinder radius="0.028" length="0.30"/></geometry>
      <material name="blue"/>
    </visual>
    <collision>
      <origin xyz="0.15 0 0" rpy="0 1.5708 0"/>
      <geometry><cylinder radius="0.028" length="0.30"/></geometry>
    </collision>
    <inertial>
      <mass value="2.0"/>
      <inertia ixx="0.01" iyy="0.01" izz="0.01" ixy="0" ixz="0" iyz="0"/>
    </inertial>
  </link>

  <!-- J4: primo asse polso (asse Y) -->
  <joint name="joint4" type="revolute">
    <parent link="link3"/>
    <child link="link4"/>
    <origin xyz="0.30 0 0" rpy="0 0 0"/>
    <axis xyz="0 1 0"/>
    <limit lower="-3.1416" upper="3.1416" effort="50" velocity="3.0"/>
  </joint>

  <link name="link4">
    <visual>
      <origin xyz="0.10 0 0" rpy="0 1.5708 0"/>
      <geometry><cylinder radius="0.025" length="0.20"/></geometry>
      <material name="gray"/>
    </visual>
    <collision>
      <origin xyz="0.10 0 0" rpy="0 1.5708 0"/>
      <geometry><cylinder radius="0.025" length="0.20"/></geometry>
    </collision>
    <inertial>
      <mass value="1.0"/>
      <inertia ixx="0.005" iyy="0.005" izz="0.005" ixy="0" ixz="0" iyz="0"/>
    </inertial>
  </link>

  <!-- J5: secondo asse polso (asse X) -->
  <joint name="joint5" type="revolute">
    <parent link="link4"/>
    <child link="link5"/>
    <origin xyz="0.20 0 0" rpy="0 0 0"/>
    <axis xyz="1 0 0"/>
    <limit lower="-3.1416" upper="3.1416" effort="40" velocity="3.0"/>
  </joint>

  <link name="link5">
    <visual>
      <origin xyz="0.05 0 0" rpy="0 1.5708 0"/>
      <geometry><cylinder radius="0.022" length="0.10"/></geometry>
      <material name="blue"/>
    </visual>
    <collision>
      <origin xyz="0.05 0 0" rpy="0 1.5708 0"/>
      <geometry><cylinder radius="0.022" length="0.10"/></geometry>
    </collision>
    <inertial>
      <mass value="0.5"/>
      <inertia ixx="0.003" iyy="0.003" izz="0.003" ixy="0" ixz="0" iyz="0"/>
    </inertial>
  </link>

  <!-- J6: terzo asse polso (asse Z) -->
  <joint name="joint6" type="revolute">
    <parent link="link5"/>
    <child link="tool0"/>
    <origin xyz="0.10 0 0" rpy="0 0 0"/>
    <axis xyz="0 0 1"/>
    <limit lower="-3.1416" upper="3.1416" effort="30" velocity="4.0"/>
  </joint>

  <!-- Flangia utensile -->
  <link name="tool0">
    <visual>
      <origin xyz="0 0 0.05" rpy="0 0 0"/>
      <geometry><cylinder radius="0.02" length="0.10"/></geometry>
      <material name="gray"/>
    </visual>
    <collision>
      <origin xyz="0 0 0.05" rpy="0 0 0"/>
      <geometry><cylinder radius="0.02" length="0.10"/></geometry>
    </collision>
    <inertial>
      <mass value="0.3"/>
      <inertia ixx="0.001" iyy="0.001" izz="0.001" ixy="0" ixz="0" iyz="0"/>
    </inertial>
  </link>

</robot>
