<?xml version="1.0"?>
<robot name="planar_arm">
  <material name="blue"><color rgba="0 0 1 1"/></material>
  <material name="green"><color rgba="0 1 0 1"/></material>
  <material name="yellow"><color rgba="1 1 0 1"/></material>
  <material name="red"><color rgba="1 0 0 1"/></material>

  <link name="base_link">
    <visual>
      <origin xyz="0 0 0.25" rpy="0 0 0"/>
      <geometry><cylinder radius="0.1" length="0.5"/></geometry>
      <material name="blue"/>
    </visual>

    <collision>    
      <origin xyz="0 0 0.25" rpy="0 0 0"/>
      <geometry><cylinder radius="0.1" length="0.5"/></geometry>
    </collision>
    
    <inertial>
      <origin xyz="0 0 0" rpy="0 0 0"/>
      <mass value="1.0"/>
      <inertia ixx="0.01" ixy="0.0" ixz="0.0" iyy="0.01" iyz="0.0" izz="0.01"/>
    </inertial>
  </link>

  <joint name="joint1" type="revolute">
    <parent link="base_link"/>
    <child link="link1"/>
    <origin xyz="0 0 0.5" rpy="0 0 0"/>
    <axis xyz="0 0 1"/>
    <limit effort="100.0" lower="-3.14" upper="3.14" velocity="1.0"/>
  </joint>

  <link name="link1">
    <visual>
      <origin xyz="0.5 0 0" rpy="0 1.5708 0"/>
      <geometry><cylinder radius="0.05" length="1.0"/></geometry>
      <material name="green"/>
    </visual>

    <collision>    
      <origin xyz="0.5 0 0" rpy="0 1.5708 0"/>
      <geometry><cylinder radius="0.05" length="1.0"/></geometry>
      <material name="green"/>
    </collision>

    <inertial>
      <origin xyz="0 0 0" rpy="0 0 0"/>
      <mass value="1.0"/>
      <inertia ixx="0.01" ixy="0.0" ixz="0.0" iyy="0.01" iyz="0.0" izz="0.01"/>
    </inertial>
  </link>

  <joint name="joint2" type="revolute">
    <parent link="link1"/>
    <child link="link2"/>
    <origin xyz="1.0 0 0" rpy="0 0 0"/>
    <axis xyz="0 0 1"/>
    <limit effort="100.0" lower="-3.14" upper="3.14" velocity="1.0"/>
  </joint>

  <link name="link2">
    <visual>
      <origin xyz="0.5 0 0" rpy="0 1.5708 0"/>
      <geometry><cylinder radius="0.05" length="1.0"/></geometry>
      <material name="yellow"/>
    </visual>

    <collision>
      <origin xyz="0.5 0 0" rpy="0 1.5708 0"/>
      <geometry><cylinder radius="0.05" length="1.0"/></geometry>
      <material name="yellow"/>
    </collision>

    <inertial>
      <origin xyz="0 0 0" rpy="0 0 0"/>
      <mass value="1.0"/>
      <inertia ixx="0.01" ixy="0.0" ixz="0.0" iyy="0.01" iyz="0.0" izz="0.01"/>
    </inertial>
  </link>

  <joint name="joint3" type="revolute">
    <parent link="link2"/>
    <child link="link3"/>
    <origin xyz="1.0 0 0" rpy="0 0 0"/>
    <axis xyz="0 0 1"/>
    <limit effort="100.0" lower="-3.14" upper="3.14" velocity="1.0"/>
  </joint>

  <link name="link3">
    <visual>
      <origin xyz="0.5 0 0" rpy="0 1.5708 0"/>
      <geometry><cylinder radius="0.05" length="1.0"/></geometry>
      <material name="red"/>
    </visual>

    <collision>
      <origin xyz="0.5 0 0" rpy="0 1.5708 0"/>
      <geometry><cylinder radius="0.05" length="1.0"/></geometry>
      <material name="red"/>
    </collision>

    <inertial>
      <origin xyz="0 0 0" rpy="0 0 0"/>
      <mass value="1.0"/>
      <inertia ixx="0.01" ixy="0.0" ixz="0.0" iyy="0.01" iyz="0.0" izz="0.01"/>
    </inertial>
  </link>

  <joint name="joint4" type="fixed">
    <parent link="link3"/>
    <child link="end_effector"/>
    <origin xyz="1.0 0 0" rpy="0 0 0"/>
  </joint>

  <link name="end_effector">
    <visual>
      <origin xyz="0 0 0" rpy="0 0 0"/>
      <geometry><sphere radius="0.05"/></geometry>
      <material name="red"/>
    </visual>

    <collision>
      <origin xyz="0 0 0" rpy="0 0 0"/>
      <geometry><sphere radius="0.05"/></geometry>
      <material name="red"/>
    </collision>

    <inertial>
      <origin xyz="0 0 0" rpy="0 0 0"/>
      <mass value="0.2"/>
      <inertia ixx="0.001" ixy="0.0" ixz="0.0" iyy="0.001" iyz="0.0" izz="0.001"/>
    </inertial>
  </link>

  
</robot>
