<sdf version='1.11'>
  <model name='planar_arm'>
    <link name='base_link'>
      <inertial>
        <pose>0 0 0 0 0 0</pose>
        <mass>1</mass>
        <inertia>
          <ixx>0.01</ixx>
          <ixy>0</ixy>
          <ixz>0</ixz>
          <iyy>0.01</iyy>
          <iyz>0</iyz>
          <izz>0.01</izz>
        </inertia>
      </inertial>
      <collision name='base_link_collision'>
        <pose>0 0 0.25 0 0 0</pose>
        <geometry>
          <cylinder>
            <length>0.5</length>
            <radius>0.10000000000000001</radius>
          </cylinder>
        </geometry>
      </collision>
      <visual name='base_link_visual'>
        <pose>0 0 0.25 0 0 0</pose>
        <geometry>
          <cylinder>
            <length>0.5</length>
            <radius>0.10000000000000001</radius>
          </cylinder>
        </geometry>
        <material>
          <diffuse>0 0 1 1</diffuse>
          <ambient>0 0 1 1</ambient>
        </material>
      </visual>
    </link>

    <joint name='joint1' type='revolute'>
      <pose relative_to='base_link'>0 0 0.5 0 0 0</pose>
      <parent>base_link</parent>
      <child>link1</child>
      <axis>
        <xyz>0 1 0</xyz>
        <limit>
          <lower>-3.1400000000000001</lower>
          <upper>3.1400000000000001</upper>
          <effort>100</effort>
          <velocity>1</velocity>
        </limit>
        <dynamics>
          <spring_reference>0</spring_reference>
          <spring_stiffness>0</spring_stiffness>
        </dynamics>
      </axis>
    </joint>

    <link name='link1'>
      <pose relative_to='joint1'>0 0 0 0 0 0</pose>
      <inertial>
        <pose>0 0 0 0 0 0</pose>
        <mass>1</mass>
        <inertia>
          <ixx>0.01</ixx>
          <ixy>0</ixy>
          <ixz>0</ixz>
          <iyy>0.01</iyy>
          <iyz>0</iyz>
          <izz>0.01</izz>
        </inertia>
      </inertial>
      <collision name='link1_collision'>
        <pose>0.5 0 0 0 1.5707963267948966 0</pose>
        <geometry>
          <cylinder>
            <length>1</length>
            <radius>0.050000000000000003</radius>
          </cylinder>
        </geometry>
      </collision>
      <visual name='link1_visual'>
        <pose>0.5 0 0 0 0 0</pose>
        <geometry>
          <cylinder>
            <length>1</length>
            <radius>0.050000000000000003</radius>
          </cylinder>
        </geometry>
        <material>
          <diffuse>0 1 0 1</diffuse>
          <ambient>0 1 0 1</ambient>
        </material>
      </visual>
    </link>

    <joint name='joint2' type='revolute'>
      <pose relative_to='link1'>1 0 0 0 0 0</pose>
      <parent>link1</parent>
      <child>link2</child>
      <axis>
        <xyz>0 1 0</xyz>
        <limit>
          <lower>-3.1400000000000001</lower>
          <upper>3.1400000000000001</upper>
          <effort>100</effort>
          <velocity>1</velocity>
        </limit>
        <dynamics>
          <spring_reference>0</spring_reference>
          <spring_stiffness>0</spring_stiffness>
        </dynamics>
      </axis>
    </joint>

    <link name='link2'>
      <pose relative_to='joint2'>0 0 0 0 0 0</pose>
      <inertial>
        <pose>0 0 0 0 0 0</pose>
        <mass>1</mass>
        <inertia>
          <ixx>0.01</ixx>
          <ixy>0</ixy>
          <ixz>0</ixz>
          <iyy>0.01</iyy>
          <iyz>0</iyz>
          <izz>0.01</izz>
        </inertia>
      </inertial>
      <collision name='link2_collision'>
        <pose>0.5 0 0 0 1.5707963267948966 0</pose>
        <geometry>
          <cylinder>
            <length>1</length>
            <radius>0.050000000000000003</radius>
          </cylinder>
        </geometry>
      </collision>
      <visual name='link2_visual'>
        <pose>0.5 0 0 0 0 0</pose>
        <geometry>
          <cylinder>
            <length>1</length>
            <radius>0.050000000000000003</radius>
          </cylinder>
        </geometry>
        <material>
          <diffuse>1 1 0 1</diffuse>
          <ambient>1 1 0 1</ambient>
        </material>
      </visual>
    </link>

    <joint name='joint3' type='revolute'>
      <pose relative_to='link2'>1 0 0 0 0 0</pose>
      <parent>link2</parent>
      <child>link3</child>
      <axis>
        <xyz>0 1 0</xyz>
        <limit>
          <lower>-3.1400000000000001</lower>
          <upper>3.1400000000000001</upper>
          <effort>100</effort>
          <velocity>1</velocity>
        </limit>
        <dynamics>
          <spring_reference>0</spring_reference>
          <spring_stiffness>0</spring_stiffness>
        </dynamics>
      </axis>
    </joint>

    <link name='link3'>
      <pose relative_to='joint3'>0 0 0 0 0 0</pose>
      <inertial>
        <pose>0.16666666666666671 0 0 0 0 0</pose>
        <mass>1.2</mass>
        <inertia>
          <ixx>0.010999999999999999</ixx>
          <ixy>0</ixy>
          <ixz>0</ixz>
          <iyy>0.17766666666666669</iyy>
          <iyz>0</iyz>
          <izz>0.17766666666666669</izz>
        </inertia>
      </inertial>
      <collision name='link3_collision'>
        <pose>0.5 0 0 0 1.5707963267948966 0</pose>
        <geometry>
          <cylinder>
            <length>1</length>
            <radius>0.050000000000000003</radius>
          </cylinder>
        </geometry>
      </collision>
      <collision name='link3_fixed_joint_lump__end_effector_collision_1'>
        <pose>1 0 0 0 0 0</pose>
        <geometry>
          <sphere>
            <radius>0.050000000000000003</radius>
          </sphere>
        </geometry>
      </collision>
      <visual name='link3_visual'>
        <pose>0.5 0 0 0 0 0</pose>
        <geometry>
          <cylinder>
            <length>1</length>
            <radius>0.050000000000000003</radius>
          </cylinder>
        </geometry>
        <material>
          <diffuse>1 0 0 1</diffuse>
          <ambient>1 0 0 1</ambient>
        </material>
      </visual>
      <visual name='link3_fixed_joint_lump__end_effector_visual_1'>
        <pose>1 0 0 0 0 0</pose>
        <geometry>
          <sphere>
            <radius>0.050000000000000003</radius>
          </sphere>
        </geometry>
        <material>
          <diffuse>1 0 0 1</diffuse>
          <ambient>1 0 0 1</ambient>
        </material>
      </visual>
    </link>

    <frame name='joint4' attached_to='link3'>
      <pose>1 0 0 0 0 0</pose>
    </frame>
    <frame name='end_effector' attached_to='joint4'>
      <pose>0 0 0 0 0 0</pose>
    </frame>

    <!-- joint1 -->
    <plugin filename="gz-sim-joint-position-controller-system"
            name="gz::sim::systems::JointPositionController">
      <joint_name>joint1</joint_name>
      <topic>/model/planar_arm/joint/joint1/cmd_pos</topic>
      <!-- opzionale: <position_p_gain>10.0</position_p_gain> -->
    </plugin>

    <!-- joint2 -->
    <plugin filename="gz-sim-joint-position-controller-system"
            name="gz::sim::systems::JointPositionController">
      <joint_name>joint2</joint_name>
      <topic>/model/planar_arm/joint/joint2/cmd_pos</topic>
    </plugin>

    <!-- joint3 -->
    <plugin filename="gz-sim-joint-position-controller-system"
            name="gz::sim::systems::JointPositionController">
      <joint_name>joint3</joint_name>
      <topic>/model/planar_arm/joint/joint3/cmd_pos</topic>
    </plugin>

  </model>
</sdf>
